<?xml version="1.0" ?>
<robot name="robocup_bot" xmlns:xacro="http://www.ros.org/wiki/xacro">

<xacro:include filename="$(find robocup_bot_description)/urdf/materials.xacro" />
<xacro:include filename="$(find robocup_bot_description)/urdf/robocup_bot.trans" />
<xacro:include filename="$(find robocup_bot_description)/urdf/robocup_bot.gazebo" />
<xacro:include filename="$(find robocup_bot_description)/urdf/camera.xacro" />
<xacro:include filename="$(find robocup_bot_description)/urdf/gazebo_control.xacro" />
<link name="base_link">
  <inertial>
    <origin xyz="0.20000000000000004 0.20047111181734686 0.2359412711182623" rpy="0 0 0"/>
    <mass value="341.51424999999995"/>
    <inertia ixx="18.693283" iyy="18.693146" izz="5.443908" ixy="0.0" iyz="-0.039498" ixz="0.0"/>
  </inertial>
  <visual>
    <origin xyz="0 0 0" rpy="0 0 0"/>
    <geometry>
      <mesh filename="file://$(find robocup_bot_description)/meshes/base_link.stl" scale="0.001 0.001 0.001"/>
    </geometry>
    <material name="silver"/>
  </visual>
  <collision>
    <origin xyz="0 0 0" rpy="0 0 0"/>
    <geometry>
      <mesh filename="file://$(find robocup_bot_description)/meshes/base_link.stl" scale="0.001 0.001 0.001"/>
    </geometry>
  </collision>
</link>

<gazebo reference = "base_link">
  <material>Gazebo/White</material>
</gazebo>

<link name="wheel4_1">
  <inertial>
    <origin xyz="-0.017677669529663785 0.017677669529663653 0.0" rpy="0 0 0"/>
    <mass value="3.0826877913349864"/>
    <inertia ixx="0.003211" iyy="0.003211" izz="0.002569" ixy="-0.000642" iyz="0.0" ixz="0.0"/>
  </inertial>
  <visual>
    <origin xyz="-0.05 -0.35 -0.0" rpy="0 0 0"/>
    <geometry>
      <mesh filename="file://$(find robocup_bot_description)/meshes/wheel4_1.stl" scale="0.001 0.001 0.001"/>
    </geometry>
    <material name="black"/>
  </visual>
  <collision>
    <origin xyz="-0.05 -0.35 -0.0" rpy="0 0 0"/>
    <geometry>
      <mesh filename="file://$(find robocup_bot_description)/meshes/wheel4_1.stl" scale="0.001 0.001 0.001"/>
    </geometry>
  </collision>
</link>
<gazebo reference = "wheel4_1">
  <material>Gazebo/Black</material>
</gazebo>

<link name="wheel2_1">
  <inertial>
    <origin xyz="0.017677669529663764 -0.01767766952966364 0.0" rpy="0 0 0"/>
    <mass value="3.0826877913349757"/>
    <inertia ixx="0.003211" iyy="0.003211" izz="0.002569" ixy="-0.000642" iyz="-0.0" ixz="0.0"/>
  </inertial>
  <visual>
    <origin xyz="-0.35 -0.05 -0.0" rpy="0 0 0"/>
    <geometry>
      <mesh filename="file://$(find robocup_bot_description)/meshes/wheel2_1.stl" scale="0.001 0.001 0.001"/>
    </geometry>
    <material name="black"/>
  </visual>
  <collision>
    <origin xyz="-0.35 -0.05 -0.0" rpy="0 0 0"/>
    <geometry>
      <mesh filename="file://$(find robocup_bot_description)/meshes/wheel2_1.stl" scale="0.001 0.001 0.001"/>
    </geometry>
  </collision>
</link>
<gazebo reference = "wheel2_1">
  <material>Gazebo/Black</material>
</gazebo>

<link name="wheel1_1">
  <inertial>
    <origin xyz="-0.017677669529663716 -0.017677669529663716 0.0" rpy="0 0 0"/>
    <mass value="3.0826877913349864"/>
    <inertia ixx="0.003211" iyy="0.003211" izz="0.002569" ixy="0.000642" iyz="0.0" ixz="0.0"/>
  </inertial>
  <visual>
    <origin xyz="-0.05 -0.05 -0.0" rpy="0 0 0"/>
    <geometry>
      <mesh filename="file://$(find robocup_bot_description)/meshes/wheel1_1.stl" scale="0.001 0.001 0.001"/>
    </geometry>
    <material name="black"/>
  </visual>
  <collision>
    <origin xyz="-0.05 -0.05 -0.0" rpy="0 0 0"/>
    <geometry>
      <mesh filename="file://$(find robocup_bot_description)/meshes/wheel1_1.stl" scale="0.001 0.001 0.001"/>
    </geometry>
  </collision>
</link>
<gazebo reference = "wheel1_1">
  <material>Gazebo/Black</material>
</gazebo>

<link name="wheel3_1">
  <inertial>
    <origin xyz="0.017677669529663376 0.017677669529663764 0.0" rpy="0 0 0"/>
    <mass value="3.082687791334989"/>
    <inertia ixx="0.003211" iyy="0.003211" izz="0.002569" ixy="0.000642" iyz="-0.0" ixz="0.0"/>
  </inertial>
  <visual>
    <origin xyz="-0.35 -0.35 -0.0" rpy="0 0 0"/>
    <geometry>
      <mesh filename="file://$(find robocup_bot_description)/meshes/wheel3_1.stl" scale="0.001 0.001 0.001"/>
    </geometry>
    <material name="black"/>
  </visual>
  <collision>
    <origin xyz="-0.35 -0.35 -0.0" rpy="0 0 0"/>
    <geometry>
      <mesh filename="file://$(find robocup_bot_description)/meshes/wheel3_1.stl" scale="0.001 0.001 0.001"/>
    </geometry>
  </collision>
</link>
<gazebo reference = "wheel3_1">
  <material>Gazebo/Black</material>
</gazebo>

<link name="cam1_1">
  <inertial>
    <origin xyz="-0.007500000000000007 -1.2192107856634493e-07 1.1102230246251565e-16" rpy="0 0 0"/>
    <mass value="0.23120158435012447"/>
    <inertia ixx="7.2e-05" iyy="4e-05" izz="4e-05" ixy="-0.0" iyz="0.0" ixz="-0.0"/>
  </inertial>
  <visual>
    <origin xyz="-0.15 -0.201322 -0.9" rpy="0 0 0"/>
    <geometry>
      <mesh filename="file://$(find robocup_bot_description)/meshes/cam1_1.stl" scale="0.001 0.001 0.001"/>
    </geometry>
    <material name="red"/>
  </visual>
  <collision>
    <origin xyz="-0.15 -0.201322 -0.9" rpy="0 0 0"/>
    <geometry>
      <mesh filename="file://$(find robocup_bot_description)/meshes/cam1_1.stl" scale="0.001 0.001 0.001"/>
    </geometry>
  </collision>
</link>
<gazebo reference = "cam1_1">
  <material>Gazebo/Red</material>
</gazebo>

<link name="cam2_1">
  <inertial>
    <origin xyz="0.0 0.00749987807892144 0.0" rpy="0 0 0"/>
    <mass value="0.23120158435012242"/>
    <inertia ixx="4e-05" iyy="7.2e-05" izz="4e-05" ixy="0.0" iyz="0.0" ixz="-0.0"/>
  </inertial>
  <visual>
    <origin xyz="-0.2 -0.251322 -0.9" rpy="0 0 0"/>
    <geometry>
      <mesh filename="file://$(find robocup_bot_description)/meshes/cam2_1.stl" scale="0.001 0.001 0.001"/>
    </geometry>
    <material name="red"/>
  </visual>
  <collision>
    <origin xyz="-0.2 -0.251322 -0.9" rpy="0 0 0"/>
    <geometry>
      <mesh filename="file://$(find robocup_bot_description)/meshes/cam2_1.stl" scale="0.001 0.001 0.001"/>
    </geometry>
  </collision>
</link>
<gazebo reference = "cam2_1">
  <material>Gazebo/Red</material>
</gazebo>

<link name="cam3_1">
  <inertial>
    <origin xyz="0.007500000000000007 -1.2192107856634493e-07 0.0" rpy="0 0 0"/>
    <mass value="0.2312015843501238"/>
    <inertia ixx="7.2e-05" iyy="4e-05" izz="4e-05" ixy="-0.0" iyz="-0.0" ixz="0.0"/>
  </inertial>
  <visual>
    <origin xyz="-0.25 -0.201322 -0.9" rpy="0 0 0"/>
    <geometry>
      <mesh filename="file://$(find robocup_bot_description)/meshes/cam3_1.stl" scale="0.001 0.001 0.001"/>
    </geometry>
    <material name="red"/>
  </visual>
  <collision>
    <origin xyz="-0.25 -0.201322 -0.9" rpy="0 0 0"/>
    <geometry>
      <mesh filename="file://$(find robocup_bot_description)/meshes/cam3_1.stl" scale="0.001 0.001 0.001"/>
    </geometry>
  </collision>
</link>
<gazebo reference = "cam3_1">
  <material>Gazebo/Red</material>
</gazebo>

<link name="cam4_1">
  <inertial>
    <origin xyz="0.0 -0.007500121921078573 0.0" rpy="0 0 0"/>
    <mass value="0.2312015843501238"/>
    <inertia ixx="4e-05" iyy="7.2e-05" izz="4e-05" ixy="0.0" iyz="0.0" ixz="0.0"/>
  </inertial>
  <visual>
    <origin xyz="-0.2 -0.151322 -0.9" rpy="0 0 0"/>
    <geometry>
      <mesh filename="file://$(find robocup_bot_description)/meshes/cam4_1.stl" scale="0.001 0.001 0.001"/>
    </geometry>
    <material name="red"/>
  </visual>
  <collision>
    <origin xyz="-0.2 -0.151322 -0.9" rpy="0 0 0"/>
    <geometry>
      <mesh filename="file://$(find robocup_bot_description)/meshes/cam4_1.stl" scale="0.001 0.001 0.001"/>
    </geometry>
  </collision>
</link>
<gazebo reference = "cam4_1">
  <material>Gazebo/Red</material>
</gazebo>

<joint name="wheel42base" type="continuous">
  <origin xyz="0.05 0.35 0.0" rpy="0 0 0"/>
  <parent link="base_link"/>
  <child link="wheel4_1"/>
  <axis xyz="-0.707107 0.707107 0.0"/>
</joint>

<joint name="wheel22base" type="continuous">
  <origin xyz="0.35 0.05 0.0" rpy="0 0 0"/>
  <parent link="base_link"/>
  <child link="wheel2_1"/>
  <axis xyz="0.707107 -0.707107 0.0"/>
</joint>

<joint name="wheel32base" type="continuous">
  <origin xyz="0.05 0.05 0.0" rpy="0 0 0"/>
  <parent link="base_link"/>
  <child link="wheel1_1"/>
  <axis xyz="-0.707107 -0.707107 0.0"/>
</joint>

<joint name="wheel12base" type="continuous">
  <origin xyz="0.35 0.35 0.0" rpy="0 0 0"/>
  <parent link="base_link"/>
  <child link="wheel3_1"/>
  <axis xyz="0.707107 0.707107 0.0"/>
</joint>

<joint name="cam12base" type="fixed">
  <origin xyz="0.15 0.201322 0.9" rpy="0 0 0"/>
  <parent link="base_link"/>
  <child link="cam1_1"/>
</joint>

<joint name="cam22base" type="fixed">
  <origin xyz="0.2 0.251322 0.9" rpy="0 0 0"/>
  <parent link="base_link"/>
  <child link="cam2_1"/>
</joint>

<joint name="Rigid 15" type="fixed">
  <origin xyz="0.25 0.201322 0.9" rpy="0 0 0"/>
  <parent link="base_link"/>
  <child link="cam3_1"/>
</joint>

<joint name="Rigid 16" type="fixed">
  <origin xyz="0.2 0.151322 0.9" rpy="0 0 0"/>
  <parent link="base_link"/>
  <child link="cam4_1"/>
</joint>

</robot>